Traceback (most recent call last):
  File "C:\Users\Janareis\AppData\Local\Programs\Python\Python310\lib\site-packages\jupyter_cache\executors\utils.py", line 58, in single_nb_execution
    executenb(
  File "C:\Users\Janareis\AppData\Local\Programs\Python\Python310\lib\site-packages\nbclient\client.py", line 1305, in execute
    return NotebookClient(nb=nb, resources=resources, km=km, **kwargs).execute()
  File "C:\Users\Janareis\AppData\Local\Programs\Python\Python310\lib\site-packages\jupyter_core\utils\__init__.py", line 173, in wrapped
    return loop.run_until_complete(inner)
  File "C:\Users\Janareis\AppData\Local\Programs\Python\Python310\lib\asyncio\base_events.py", line 649, in run_until_complete
    return future.result()
  File "C:\Users\Janareis\AppData\Local\Programs\Python\Python310\lib\site-packages\nbclient\client.py", line 705, in async_execute
    await self.async_execute_cell(
  File "C:\Users\Janareis\AppData\Local\Programs\Python\Python310\lib\site-packages\nbclient\client.py", line 1058, in async_execute_cell
    await self._check_raise_for_error(cell, cell_index, exec_reply)
  File "C:\Users\Janareis\AppData\Local\Programs\Python\Python310\lib\site-packages\nbclient\client.py", line 914, in _check_raise_for_error
    raise CellExecutionError.from_cell_and_msg(cell, exec_reply_content)
nbclient.exceptions.CellExecutionError: An error occurred while executing the following cell:
------------------
display_quiz(questions, colors = 'fdsp' )
------------------


[1;31m---------------------------------------------------------------------------[0m
[1;31mNameError[0m                                 Traceback (most recent call last)
Cell [1;32mIn[16], line 1[0m
[1;32m----> 1[0m [43mdisplay_quiz[49m(questions, colors [38;5;241m=[39m [38;5;124m'[39m[38;5;124mfdsp[39m[38;5;124m'[39m )

[1;31mNameError[0m: name 'display_quiz' is not defined

