Traceback (most recent call last):
  File "C:\Users\Janareis\AppData\Local\Programs\Python\Python310\lib\site-packages\jupyter_cache\executors\utils.py", line 58, in single_nb_execution
    executenb(
  File "C:\Users\Janareis\AppData\Local\Programs\Python\Python310\lib\site-packages\nbclient\client.py", line 1305, in execute
    return NotebookClient(nb=nb, resources=resources, km=km, **kwargs).execute()
  File "C:\Users\Janareis\AppData\Local\Programs\Python\Python310\lib\site-packages\jupyter_core\utils\__init__.py", line 173, in wrapped
    return loop.run_until_complete(inner)
  File "C:\Users\Janareis\AppData\Local\Programs\Python\Python310\lib\asyncio\base_events.py", line 649, in run_until_complete
    return future.result()
  File "C:\Users\Janareis\AppData\Local\Programs\Python\Python310\lib\site-packages\nbclient\client.py", line 705, in async_execute
    await self.async_execute_cell(
  File "C:\Users\Janareis\AppData\Local\Programs\Python\Python310\lib\site-packages\nbclient\client.py", line 1058, in async_execute_cell
    await self._check_raise_for_error(cell, cell_index, exec_reply)
  File "C:\Users\Janareis\AppData\Local\Programs\Python\Python310\lib\site-packages\nbclient\client.py", line 914, in _check_raise_for_error
    raise CellExecutionError.from_cell_and_msg(cell, exec_reply_content)
nbclient.exceptions.CellExecutionError: An error occurred while executing the following cell:
------------------
from scipy.signal import convolve2d

A = np.arange(12).reshape(3, 4)
B = np.array([[2, 0], [1, -1]])
print("Full:")
print(convolve2d(A, B, mode='full'))
print("Same:")
print(convolve2d(A, B, mode='same'))
print("Valid:")
print(convolve2d(A, B, mode='valid'))
------------------


[1;31m---------------------------------------------------------------------------[0m
[1;31mModuleNotFoundError[0m                       Traceback (most recent call last)
Cell [1;32mIn[5], line 1[0m
[1;32m----> 1[0m [38;5;28;01mfrom[39;00m [38;5;21;01mscipy[39;00m[38;5;21;01m.[39;00m[38;5;21;01msignal[39;00m [38;5;28;01mimport[39;00m convolve2d
[0;32m      3[0m A [38;5;241m=[39m np[38;5;241m.[39marange([38;5;241m12[39m)[38;5;241m.[39mreshape([38;5;241m3[39m, [38;5;241m4[39m)
[0;32m      4[0m B [38;5;241m=[39m np[38;5;241m.[39marray([[[38;5;241m2[39m, [38;5;241m0[39m], [[38;5;241m1[39m, [38;5;241m-[39m[38;5;241m1[39m]])

[1;31mModuleNotFoundError[0m: No module named 'scipy'

