Traceback (most recent call last):
  File "C:\Users\Janareis\AppData\Local\Programs\Python\Python310\lib\site-packages\jupyter_cache\executors\utils.py", line 58, in single_nb_execution
    executenb(
  File "C:\Users\Janareis\AppData\Local\Programs\Python\Python310\lib\site-packages\nbclient\client.py", line 1305, in execute
    return NotebookClient(nb=nb, resources=resources, km=km, **kwargs).execute()
  File "C:\Users\Janareis\AppData\Local\Programs\Python\Python310\lib\site-packages\jupyter_core\utils\__init__.py", line 173, in wrapped
    return loop.run_until_complete(inner)
  File "C:\Users\Janareis\AppData\Local\Programs\Python\Python310\lib\asyncio\base_events.py", line 649, in run_until_complete
    return future.result()
  File "C:\Users\Janareis\AppData\Local\Programs\Python\Python310\lib\site-packages\nbclient\client.py", line 705, in async_execute
    await self.async_execute_cell(
  File "C:\Users\Janareis\AppData\Local\Programs\Python\Python310\lib\site-packages\nbclient\client.py", line 1058, in async_execute_cell
    await self._check_raise_for_error(cell, cell_index, exec_reply)
  File "C:\Users\Janareis\AppData\Local\Programs\Python\Python310\lib\site-packages\nbclient\client.py", line 914, in _check_raise_for_error
    raise CellExecutionError.from_cell_and_msg(cell, exec_reply_content)
nbclient.exceptions.CellExecutionError: An error occurred while executing the following cell:
------------------
import torch
from torch import nn

conv = nn.Conv2d(1, 1, 3, bias=False, padding=1)
conv.weight = nn.parameter.Parameter(torch.FloatTensor(B[None, None, :, :]))
print("Full:")
print(conv(torch.FloatTensor(A[None, None, :, :])).detach().numpy().squeeze())

conv = nn.Conv2d(1, 1, 3, bias=False, padding='same')
conv.weight = nn.parameter.Parameter(torch.FloatTensor(B[None, None, :, :]))
print("Same:")
print(conv(torch.FloatTensor(A[None, None, :, :])).detach().numpy().squeeze())

conv = nn.Conv2d(1, 1, 3, bias=False, padding='valid')
conv.weight = nn.parameter.Parameter(torch.FloatTensor(B[None, None, :, :]))
print("Valid:")
print(conv(torch.FloatTensor(A[None, None, :, :])).detach().numpy().squeeze())
------------------


[1;31m---------------------------------------------------------------------------[0m
[1;31mModuleNotFoundError[0m                       Traceback (most recent call last)
Cell [1;32mIn[6], line 1[0m
[1;32m----> 1[0m [38;5;28;01mimport[39;00m [38;5;21;01mtorch[39;00m
[0;32m      2[0m [38;5;28;01mfrom[39;00m [38;5;21;01mtorch[39;00m [38;5;28;01mimport[39;00m nn
[0;32m      4[0m conv [38;5;241m=[39m nn[38;5;241m.[39mConv2d([38;5;241m1[39m, [38;5;241m1[39m, [38;5;241m3[39m, bias[38;5;241m=[39m[38;5;28;01mFalse[39;00m, padding[38;5;241m=[39m[38;5;241m1[39m)

[1;31mModuleNotFoundError[0m: No module named 'torch'

